Workbook

Sheet Assumptions
A1: Assumption | B1: Value | D1: Loan Types | E1: Down Payment Percentage
A2: Des Moines Property Tax Rate | B2: 0.01565 | D2: FHA | E2: 0.035
A3: Vacancy Rate | B3: =1/12 | D3: Conventional - 5% | E3: 0.05
A4: Repair Cost Savings Rate | B4: =0.05
A5: Closing Costs Rate | B5: 0.04
A6: Interest Rate | B6: 0.0622
A7: FHA Upfront MIP | B7: 0.0175
A8: Annual MIP | B8: =0.0085
A9: Loan Length in Years | B9: 30
A10: Property Tax Rate | B10: 0
A11: Property Appreciation Rate | B11: 0.02

Sheet Master
A1: Property ID | B1: Beds | C1: Baths | D1: Sqr ft | E1: Units | F1: Purchase Price | G1: Cash Needed FHA | H1: Cash Needed 5% Down | I1: Monthly Cost FHA | J1: Monthly Cost 5% Down | K1: Cashflow Y1 FHA | L1: Cashflow Y1 5% Down | M1: Cashflow Y2 FHA | N1: Cashflow Y2 5% Down | O1: Cap rate Y2 FHA | P1: Cap rate Y2 5% Down | Q1: CoC Y1 FHA | R1: CoC Y1 5% Down
A2: 518 35th St | B2: {=INDIRECT("'"&$A2&"'!B5",TRUE)} | C2: {=INDIRECT("'"&$A2&"'!B6",TRUE)} | D2: {=INDIRECT("'"&$A2&"'!B4",TRUE)} | E2: {=INDIRECT("'"&$A2&"'!B2",TRUE)} | F2: {=INDIRECT("'"&$A2&"'!B3",TRUE)} | G2: {=INDIRECT("'"&$A2&"'!B35",TRUE)} | H2: {=INDIRECT("'"&$A2&"'!C35",TRUE)} | I2: {=INDIRECT("'"&$A2&"'!B34",TRUE)} | J2: {=INDIRECT("'"&$A2&"'!C34",TRUE)} | K2: {=INDIRECT("'"&$A2&"'!B46",TRUE)} | L2: {=INDIRECT("'"&$A2&"'!C46",TRUE)} | M2: {=INDIRECT("'"&$A2&"'!B47",TRUE)} | N2: {=INDIRECT("'"&$A2&"'!C47",TRUE)} | O2: {=INDIRECT("'"&$A2&"'!B53",TRUE)} | P2: {=INDIRECT("'"&$A2&"'!C53",TRUE)} | Q2: {=INDIRECT("'"&$A2&"'!B54",TRUE)} | R2: {=INDIRECT("'"&$A2&"'!C54",TRUE)}
A3: 1175 21st St | B3: {=INDIRECT("'"&$A3&"'!B5",TRUE)} | C3: {=INDIRECT("'"&$A3&"'!B6",TRUE)} | D3: {=INDIRECT("'"&$A3&"'!B4",TRUE)} | E3: {=INDIRECT("'"&$A3&"'!B2",TRUE)} | F3: {=INDIRECT("'"&$A3&"'!B3",TRUE)} | G3: {=INDIRECT("'"&$A3&"'!B35",TRUE)} | H3: {=INDIRECT("'"&$A3&"'!C35",TRUE)} | I3: {=INDIRECT("'"&$A3&"'!B34",TRUE)} | J3: {=INDIRECT("'"&$A3&"'!C34",TRUE)} | K3: {=INDIRECT("'"&$A3&"'!B46",TRUE)} | L3: {=INDIRECT("'"&$A3&"'!C46",TRUE)} | M3: {=INDIRECT("'"&$A3&"'!B47",TRUE)} | N3: {=INDIRECT("'"&$A3&"'!C47",TRUE)} | O3: {=INDIRECT("'"&$A3&"'!B53",TRUE)} | P3: {=INDIRECT("'"&$A3&"'!C53",TRUE)} | Q3: {=INDIRECT("'"&$A3&"'!B54",TRUE)} | R3: {=INDIRECT("'"&$A3&"'!C54",TRUE)}
A4: 1514 Harrison Ave | B4: {=INDIRECT("'"&$A4&"'!B5",TRUE)} | C4: {=INDIRECT("'"&$A4&"'!B6",TRUE)} | D4: {=INDIRECT("'"&$A4&"'!B4",TRUE)} | E4: {=INDIRECT("'"&$A4&"'!B2",TRUE)} | F4: {=INDIRECT("'"&$A4&"'!B3",TRUE)} | G4: {=INDIRECT("'"&$A4&"'!B35",TRUE)} | H4: {=INDIRECT("'"&$A4&"'!C35",TRUE)} | I4: {=INDIRECT("'"&$A4&"'!B34",TRUE)} | J4: {=INDIRECT("'"&$A4&"'!C34",TRUE)} | K4: {=INDIRECT("'"&$A4&"'!B46",TRUE)} | L4: {=INDIRECT("'"&$A4&"'!C46",TRUE)} | M4: {=INDIRECT("'"&$A4&"'!B47",TRUE)} | N4: {=INDIRECT("'"&$A4&"'!C47",TRUE)} | O4: {=INDIRECT("'"&$A4&"'!B53",TRUE)} | P4: {=INDIRECT("'"&$A4&"'!C53",TRUE)} | Q4: {=INDIRECT("'"&$A4&"'!B54",TRUE)} | R4: {=INDIRECT("'"&$A4&"'!C54",TRUE)}
A5: 1148 36th St | B5: {=INDIRECT("'"&$A5&"'!B5",TRUE)} | C5: {=INDIRECT("'"&$A5&"'!B6",TRUE)} | D5: {=INDIRECT("'"&$A5&"'!B4",TRUE)} | E5: {=INDIRECT("'"&$A5&"'!B2",TRUE)} | F5: {=INDIRECT("'"&$A5&"'!B3",TRUE)} | G5: {=INDIRECT("'"&$A5&"'!B35",TRUE)} | H5: {=INDIRECT("'"&$A5&"'!C35",TRUE)} | I5: {=INDIRECT("'"&$A5&"'!B34",TRUE)} | J5: {=INDIRECT("'"&$A5&"'!C34",TRUE)} | K5: {=INDIRECT("'"&$A5&"'!B46",TRUE)} | L5: {=INDIRECT("'"&$A5&"'!C46",TRUE)} | M5: {=INDIRECT("'"&$A5&"'!B47",TRUE)} | N5: {=INDIRECT("'"&$A5&"'!C47",TRUE)} | O5: {=INDIRECT("'"&$A5&"'!B53",TRUE)} | P5: {=INDIRECT("'"&$A5&"'!C53",TRUE)} | Q5: {=INDIRECT("'"&$A5&"'!B54",TRUE)} | R5: {=INDIRECT("'"&$A5&"'!C54",TRUE)}
A6: 1429 Martin Luther King Jr Pkwy | B6: {=INDIRECT("'"&$A6&"'!B5",TRUE)} | C6: {=INDIRECT("'"&$A6&"'!B6",TRUE)} | D6: {=INDIRECT("'"&$A6&"'!B4",TRUE)} | E6: {=INDIRECT("'"&$A6&"'!B2",TRUE)} | F6: {=INDIRECT("'"&$A6&"'!B3",TRUE)} | G6: {=INDIRECT("'"&$A6&"'!B35",TRUE)} | H6: {=INDIRECT("'"&$A6&"'!C35",TRUE)} | I6: {=INDIRECT("'"&$A6&"'!B34",TRUE)} | J6: {=INDIRECT("'"&$A6&"'!C34",TRUE)} | K6: {=INDIRECT("'"&$A6&"'!B46",TRUE)} | L6: {=INDIRECT("'"&$A6&"'!C46",TRUE)} | M6: {=INDIRECT("'"&$A6&"'!B47",TRUE)} | N6: {=INDIRECT("'"&$A6&"'!C47",TRUE)} | O6: {=INDIRECT("'"&$A6&"'!B53",TRUE)} | P6: {=INDIRECT("'"&$A6&"'!C53",TRUE)} | Q6: {=INDIRECT("'"&$A6&"'!B54",TRUE)} | R6: {=INDIRECT("'"&$A6&"'!C54",TRUE)}
A7: 401 Franklin Ave | B7: {=INDIRECT("'"&$A7&"'!B5",TRUE)} | C7: {=INDIRECT("'"&$A7&"'!B6",TRUE)} | D7: {=INDIRECT("'"&$A7&"'!B4",TRUE)} | E7: {=INDIRECT("'"&$A7&"'!B2",TRUE)} | F7: {=INDIRECT("'"&$A7&"'!B3",TRUE)} | G7: {=INDIRECT("'"&$A7&"'!B35",TRUE)} | H7: {=INDIRECT("'"&$A7&"'!C35",TRUE)} | I7: {=INDIRECT("'"&$A7&"'!B34",TRUE)} | J7: {=INDIRECT("'"&$A7&"'!C34",TRUE)} | K7: {=INDIRECT("'"&$A7&"'!B46",TRUE)} | L7: {=INDIRECT("'"&$A7&"'!C46",TRUE)} | M7: {=INDIRECT("'"&$A7&"'!B47",TRUE)} | N7: {=INDIRECT("'"&$A7&"'!C47",TRUE)} | O7: {=INDIRECT("'"&$A7&"'!B53",TRUE)} | P7: {=INDIRECT("'"&$A7&"'!C53",TRUE)} | Q7: {=INDIRECT("'"&$A7&"'!B54",TRUE)} | R7: {=INDIRECT("'"&$A7&"'!C54",TRUE)}
A8: 1064 27th St | B8: {=INDIRECT("'"&$A8&"'!B5",TRUE)} | C8: {=INDIRECT("'"&$A8&"'!B6",TRUE)} | D8: {=INDIRECT("'"&$A8&"'!B4",TRUE)} | E8: {=INDIRECT("'"&$A8&"'!B2",TRUE)} | F8: {=INDIRECT("'"&$A8&"'!B3",TRUE)} | G8: {=INDIRECT("'"&$A8&"'!B35",TRUE)} | H8: {=INDIRECT("'"&$A8&"'!C35",TRUE)} | I8: {=INDIRECT("'"&$A8&"'!B34",TRUE)} | J8: {=INDIRECT("'"&$A8&"'!C34",TRUE)} | K8: {=INDIRECT("'"&$A8&"'!B46",TRUE)} | L8: {=INDIRECT("'"&$A8&"'!C46",TRUE)} | M8: {=INDIRECT("'"&$A8&"'!B47",TRUE)} | N8: {=INDIRECT("'"&$A8&"'!C47",TRUE)} | O8: {=INDIRECT("'"&$A8&"'!B53",TRUE)} | P8: {=INDIRECT("'"&$A8&"'!C53",TRUE)} | Q8: {=INDIRECT("'"&$A8&"'!B54",TRUE)} | R8: {=INDIRECT("'"&$A8&"'!C54",TRUE)}
A9: 1206 39th St | B9: {=INDIRECT("'"&$A9&"'!B5",TRUE)} | C9: {=INDIRECT("'"&$A9&"'!B6",TRUE)} | D9: {=INDIRECT("'"&$A9&"'!B4",TRUE)} | E9: {=INDIRECT("'"&$A9&"'!B2",TRUE)} | F9: {=INDIRECT("'"&$A9&"'!B3",TRUE)} | G9: {=INDIRECT("'"&$A9&"'!B35",TRUE)} | H9: {=INDIRECT("'"&$A9&"'!C35",TRUE)} | I9: {=INDIRECT("'"&$A9&"'!B34",TRUE)} | J9: {=INDIRECT("'"&$A9&"'!C34",TRUE)} | K9: {=INDIRECT("'"&$A9&"'!B46",TRUE)} | L9: {=INDIRECT("'"&$A9&"'!C46",TRUE)} | M9: {=INDIRECT("'"&$A9&"'!B47",TRUE)} | N9: {=INDIRECT("'"&$A9&"'!C47",TRUE)} | O9: {=INDIRECT("'"&$A9&"'!B53",TRUE)} | P9: {=INDIRECT("'"&$A9&"'!C53",TRUE)} | Q9: {=INDIRECT("'"&$A9&"'!B54",TRUE)} | R9: {=INDIRECT("'"&$A9&"'!C54",TRUE)}
A10: 1608 Mondamin Ave | B10: {=INDIRECT("'"&$A10&"'!B5",TRUE)} | C10: {=INDIRECT("'"&$A10&"'!B6",TRUE)} | D10: {=INDIRECT("'"&$A10&"'!B4",TRUE)} | E10: {=INDIRECT("'"&$A10&"'!B2",TRUE)} | F10: {=INDIRECT("'"&$A10&"'!B3",TRUE)} | G10: {=INDIRECT("'"&$A10&"'!B35",TRUE)} | H10: {=INDIRECT("'"&$A10&"'!C35",TRUE)} | I10: {=INDIRECT("'"&$A10&"'!B34",TRUE)} | J10: {=INDIRECT("'"&$A10&"'!C34",TRUE)} | K10: {=INDIRECT("'"&$A10&"'!B46",TRUE)} | L10: {=INDIRECT("'"&$A10&"'!C46",TRUE)} | M10: {=INDIRECT("'"&$A10&"'!B47",TRUE)} | N10: {=INDIRECT("'"&$A10&"'!C47",TRUE)} | O10: {=INDIRECT("'"&$A10&"'!B53",TRUE)} | P10: {=INDIRECT("'"&$A10&"'!C53",TRUE)} | Q10: {=INDIRECT("'"&$A10&"'!B54",TRUE)} | R10: {=INDIRECT("'"&$A10&"'!C54",TRUE)}
A11: 3900 11th St

Sheet 1514 Harrison Ave
A1: Property Details | B1: 1514 Harrison Ave, Des Moines, IA 50314 | E1: Conservative Claude Report Assumptions | F1: Per Month
A2: Multi-unit Type | B2: 3 | E2: 1-bed 1-bath | F2: 0
A3: Purchase Price | B3: 220000 | E3: 2-bed 1-bath | F3: 995
A4: Square Feet | B4: 2491 | E4: 3-bed 1-bath | F4: 0
A5: Bedrooms | B5: 6 | E5: 2-bed 2-bath | F5: 0
A6: Bathrooms | B6: 3 | E6: 4-bed 2-bath | F6: 0
A7: Lot Size (Sqr ft) | B7: 0 | E7: Studio | F7: 0
A8: Built in Year | B8: 1900 | E8: None | F8: 0
A9: Cost Per Square Foot | B9: =B3/B4
A12: Financials
A13: Closing Costs | B13: =$B$3*Assumptions!$B$5 | C13: =$B$3*Assumptions!$B$5
A14: Rehab Costs (Optional)
A15: Mortgage
A16: Loan Type | B16: FHA | C16: Conventional - 5%
A17: Down payment percentage | B17: =IF(B16="Conventional - 5%",0.05,0.035) | C17: =IF(C16="Conventional - 5%",0.05,0.035)
A18: Down payment amount | B18: =$B$3*B17 | C18: =$B$3*C17
A19: Base Loan Amount | B19: =$B$3-B18 | C19: =$B$3-C18
A20: FHA Fees Rolled into Loan | B20: =B3*Assumptions!$B$7 | C20: 0
A21: Final Loan Amount | B21: =B19+B20 | C21: =C19+C20
A22: Interest Rate | B22: =Assumptions!$B$6 | C22: =Assumptions!$B$6
A23: Monthly Mortgage Payment | B23: =PMT(B22/12,Assumptions!$B$9*12, -B21) | C23: =PMT(C22/12,Assumptions!$B$9*12, -C21)
A24: PMI Annual Cost | B24: =B21*Assumptions!$B$8 | C24: =C21*Assumptions!$B$8
A25: PMI Monthly Cost | B25: =B24/12 | C25: =C24/12
A26: Total PMI Cost Over the Whole Loan | B26: =B25*12*Assumptions!$B$9 | C26: =C25*12*Assumptions!$B$9
A27: Property Tax Percentage | B27: =$B$3*Assumptions!$B$2 | C27: =$B$3*Assumptions!$B$2
A28: Property Tax Per Month | B28: =B27/12 | C28: =C27/12
A29: Home Insurance Cost Per Year | B29: =$B$3*Assumptions!$B$10 | C29: =$B$3*Assumptions!$B$10
A30: Home Insurance Cost Per Month | B30: =B29/12 | C30: =C29/12
A31: Mortgage + Taxes + Insurance Monthly | B31: =B23+B25+B30+B28 | C31: =C23+C25+C30+C28
A32: Vacancy Cost Savings Per Month | B32: =Assumptions!$B$3*B31 | C32: =Assumptions!$B$3*C31
A33: Repair Cost Savings Per Month | B33: =B31*Assumptions!$B$4 | C33: =C31*Assumptions!$B$4
A34: Total Monthly Cost | B34: =SUM(B31:B33) | C34: =SUM(C31:C33)
A35: Total Upfront Cost | B35: =SUM(B13,B18) | C35: =SUM(C13,C18)
A37: Cash Flow
A38: Unit Configurations (Bed,Bath,Sqrft) | B38: Configuration | C38: Estimated Rent
A39: Unit 1 | B39: 2-bed 1-bath | C39: =VLOOKUP(B39,$E$2:$F$8,2,FALSE)
A40: Unit 2 | B40: 2-bed 1-bath | C40: =VLOOKUP(B40,$E$2:$F$8,2,FALSE)
A41: Unit 3 | B41: 2-bed 1-bath | C41: =VLOOKUP(B41,$E$2:$F$8,2,FALSE)
A42: Unit 4 | B42: None | C42: =VLOOKUP(B42,$E$2:$F$8,2,FALSE)
A43: Living in Unit… | B43: Unit 1
...

Sheet 1175 21st St
A1: Property Details | B1: https://www.zillow.com/homedetails/1175-21st-St-Des-Moines-IA-50311/772225_zpid/ | E1: Conservative Claude Report Assumptions | F1: Per Month
A2: Multi-unit Type | B2: 2 | E2: 1-bed 1-bath | F2: 0
A3: Purchase Price | B3: 212500 | E3: 2-bed 1-bath | F3: 975
A4: Square Feet | B4: 1568 | E4: 3-bed 1-bath | F4: 0
A5: Bedrooms | B5: 6 | E5: 2-bed 2-bath | F5: 0
A6: Bathrooms | B6: 3 | E6: 4-bed 2-bath | F6: 2173
A7: Lot Size (Sqr ft) | B7: 0 | E7: Studio | F7: 0
A8: Built in Year | B8: 1909 | E8: None | F8: 0
A9: Cost Per Square Foot | B9: =B3/B4
A12: Financials
A13: Closing Costs | B13: =$B$3*Assumptions!$B$5 | C13: =$B$3*Assumptions!$B$5
A14: Rehab Costs (Optional)
A15: Mortgage
A16: Loan Type | B16: FHA | C16: Conventional - 5%
A17: Down payment percentage | B17: =IF(B16="Conventional - 5%",0.05,0.035) | C17: =IF(C16="Conventional - 5%",0.05,0.035)
A18: Down payment amount | B18: =$B$3*B17 | C18: =$B$3*C17
A19: Base Loan Amount | B19: =$B$3-B18 | C19: =$B$3-C18
A20: FHA Fees Rolled into Loan | B20: =B3*Assumptions!$B$7 | C20: 0
A21: Final Loan Amount | B21: =B19+B20 | C21: =C19+C20
A22: Interest Rate | B22: =Assumptions!$B$6 | C22: =Assumptions!$B$6
A23: Monthly Mortgage Payment | B23: =PMT(B22/12,Assumptions!$B$9*12, -B21) | C23: =PMT(C22/12,Assumptions!$B$9*12, -C21)
A24: PMI Annual Cost | B24: =B21*Assumptions!$B$8 | C24: =C21*Assumptions!$B$8
A25: PMI Monthly Cost | B25: =B24/12 | C25: =C24/12
A26: Total PMI Cost Over the Whole Loan | B26: =B25*12*Assumptions!$B$9 | C26: =C25*12*Assumptions!$B$9
A27: Property Tax Percentage | B27: =$B$3*Assumptions!$B$2 | C27: =$B$3*Assumptions!$B$2
A28: Property Tax Per Month | B28: =B27/12 | C28: =C27/12
A29: Home Insurance Cost Per Year | B29: =$B$3*Assumptions!$B$10 | C29: =$B$3*Assumptions!$B$10
A30: Home Insurance Cost Per Month | B30: =B29/12 | C30: =C29/12
A31: Mortgage + Taxes + Insurance Monthly | B31: =B23+B25+B30+B28 | C31: =C23+C25+C30+C28
A32: Vacancy Cost Savings Per Month | B32: =Assumptions!$B$3*B31 | C32: =Assumptions!$B$3*C31
A33: Repair Cost Savings Per Month | B33: =B31*Assumptions!$B$4 | C33: =C31*Assumptions!$B$4
A34: Total Monthly Cost | B34: =SUM(B31:B33) | C34: =SUM(C31:C33)
A35: Total Upfront Cost | B35: =SUM(B13,B18) | C35: =SUM(C13,C18)
A37: Cash Flow
A38: Unit Configurations (Bed,Bath,Sqrft) | B38: Configuration | C38: Estimated Rent
A39: Unit 1 | B39: 2-bed 1-bath | C39: =VLOOKUP(B39,$E$2:$F$8,2,FALSE)
A40: Unit 2 | B40: 4-bed 2-bath | C40: =VLOOKUP(B40,$E$2:$F$8,2,FALSE)
A41: Unit 3 | B41: None | C41: =VLOOKUP(B41,$E$2:$F$8,2,FALSE)
A42: Unit 4 | B42: None | C42: =VLOOKUP(B42,$E$2:$F$8,2,FALSE)
A43: Living in Unit… | B43: Unit 1
...

Sheet 1429 Martin Luther King Jr Pkwy
A1: Property Details | B1: 1429 Martin Luther King Jr Pkwy, Des Moines, IA 50314 | E1: Conservative Claude Report Assumptions | F1: Per Month
A2: Multi-unit Type | B2: 2 | E2: 1-bed 1-bath | F2: 0
A3: Purchase Price | B3: 169000 | E3: 2-bed 1-bath | F3: 1100
A4: Square Feet | B4: 2544 | E4: 3-bed 1-bath | F4: 1370
A5: Bedrooms | B5: 5 | E5: 2-bed 2-bath | F5: 0
A6: Bathrooms | B6: 2 | E6: 3-bed 2-bath | F6: 0
A7: Lot Size (Sqr ft) | B7: 0 | E7: Studio | F7: 0
A8: Built in Year | B8: 1905 | E8: None | F8: 0
A9: Cost Per Square Foot | B9: =B3/B4
A12: Financials
A13: Closing Costs | B13: =$B$3*Assumptions!$B$5 | C13: =$B$3*Assumptions!$B$5
A14: Rehab Costs (Optional)
A15: Mortgage
A16: Loan Type | B16: FHA | C16: Conventional - 5%
A17: Down payment percentage | B17: =IF(B16="Conventional - 5%",0.05,0.035) | C17: =IF(C16="Conventional - 5%",0.05,0.035)
A18: Down payment amount | B18: =$B$3*B17 | C18: =$B$3*C17
A19: Base Loan Amount | B19: =$B$3-B18 | C19: =$B$3-C18
A20: FHA Fees Rolled into Loan | B20: =B3*Assumptions!$B$7 | C20: 0
A21: Final Loan Amount | B21: =B19+B20 | C21: =C19+C20
A22: Interest Rate | B22: =Assumptions!$B$6 | C22: =Assumptions!$B$6
A23: Monthly Mortgage Payment | B23: =PMT(B22/12,Assumptions!$B$9*12, -B21) | C23: =PMT(C22/12,Assumptions!$B$9*12, -C21)
A24: PMI Annual Cost | B24: =B21*Assumptions!$B$8 | C24: =C21*Assumptions!$B$8
A25: PMI Monthly Cost | B25: =B24/12 | C25: =C24/12
A26: Total PMI Cost Over the Whole Loan | B26: =B25*12*Assumptions!$B$9 | C26: =C25*12*Assumptions!$B$9
A27: Property Tax Percentage | B27: =$B$3*Assumptions!$B$2 | C27: =$B$3*Assumptions!$B$2
A28: Property Tax Per Month | B28: =B27/12 | C28: =C27/12
A29: Home Insurance Cost Per Year | B29: =$B$3*Assumptions!$B$10 | C29: =$B$3*Assumptions!$B$10
A30: Home Insurance Cost Per Month | B30: =B29/12 | C30: =C29/12
A31: Mortgage + Taxes + Insurance Monthly | B31: =B23+B25+B30+B28 | C31: =C23+C25+C30+C28
A32: Vacancy Cost Savings Per Month | B32: =Assumptions!$B$3*B31 | C32: =Assumptions!$B$3*C31
A33: Repair Cost Savings Per Month | B33: =B31*Assumptions!$B$4 | C33: =C31*Assumptions!$B$4
A34: Total Monthly Cost | B34: =SUM(B31:B33) | C34: =SUM(C31:C33)
A35: Total Upfront Cost | B35: =SUM(B13,B18) | C35: =SUM(C13,C18)
A37: Cash Flow
A38: Unit Configurations (Bed,Bath,Sqrft) | B38: Configuration | C38: Estimated Rent
A39: Unit 1 | B39: 3-bed 1-bath | C39: =VLOOKUP(B39,$E$2:$F$8,2,FALSE)
A40: Unit 2 | B40: 2-bed 1-bath | C40: =VLOOKUP(B40,$E$2:$F$8,2,FALSE)
A41: Unit 3 | B41: None | C41: =VLOOKUP(B41,$E$2:$F$8,2,FALSE)
A42: Unit 4 | B42: None | C42: =VLOOKUP(B42,$E$2:$F$8,2,FALSE)
A43: Living in Unit… | B43: Unit 2
...

Sheet 1206 39th St
A1: Property Details | B1: 1206 39th St, Des Moines, IA 50311 | E1: Conservative Claude Report Assumptions | F1: Per Month
A2: Multi-unit Type | B2: 2 | E2: 1-bed 1-bath | F2: 0
A3: Purchase Price | B3: 210000 | E3: 2-bed 1-bath | F3: 1100
A4: Square Feet | B4: 1964 | E4: 3-bed 1-bath | F4: 0
A5: Bedrooms | B5: 4 | E5: 2-bed 2-bath | F5: 1150
A6: Bathrooms | B6: 3 | E6: 3-bed 2-bath | F6: 0
A7: Lot Size (Sqr ft) | B7: 0 | E7: Studio | F7: 0
A8: Built in Year | B8: 1918 | E8: None | F8: 0
A9: Cost Per Square Foot | B9: =B3/B4
A12: Financials
A13: Closing Costs | B13: =$B$3*Assumptions!$B$5 | C13: =$B$3*Assumptions!$B$5
A14: Rehab Costs (Optional)
A15: Mortgage
A16: Loan Type | B16: FHA | C16: Conventional - 5%
A17: Down payment percentage | B17: =IF(B16="Conventional - 5%",0.05,0.035) | C17: =IF(C16="Conventional - 5%",0.05,0.035)
A18: Down payment amount | B18: =$B$3*B17 | C18: =$B$3*C17
A19: Base Loan Amount | B19: =$B$3-B18 | C19: =$B$3-C18
A20: FHA Fees Rolled into Loan | B20: =B3*Assumptions!$B$7 | C20: 0
A21: Final Loan Amount | B21: =B19+B20 | C21: =C19+C20
A22: Interest Rate | B22: =Assumptions!$B$6 | C22: =Assumptions!$B$6
A23: Monthly Mortgage Payment | B23: =PMT(B22/12,Assumptions!$B$9*12, -B21) | C23: =PMT(C22/12,Assumptions!$B$9*12, -C21)
A24: PMI Annual Cost | B24: =B21*Assumptions!$B$8 | C24: =C21*Assumptions!$B$8
A25: PMI Monthly Cost | B25: =B24/12 | C25: =C24/12
A26: Total PMI Cost Over the Whole Loan | B26: =B25*12*Assumptions!$B$9 | C26: =C25*12*Assumptions!$B$9
A27: Property Tax Percentage | B27: =$B$3*Assumptions!$B$2 | C27: =$B$3*Assumptions!$B$2
A28: Property Tax Per Month | B28: =B27/12 | C28: =C27/12
A29: Home Insurance Cost Per Year | B29: =$B$3*Assumptions!$B$10 | C29: =$B$3*Assumptions!$B$10
A30: Home Insurance Cost Per Month | B30: =B29/12 | C30: =C29/12
A31: Mortgage + Taxes + Insurance Monthly | B31: =B23+B25+B30+B28 | C31: =C23+C25+C30+C28
A32: Vacancy Cost Savings Per Month | B32: =Assumptions!$B$3*B31 | C32: =Assumptions!$B$3*C31
A33: Repair Cost Savings Per Month | B33: =B31*Assumptions!$B$4 | C33: =C31*Assumptions!$B$4
A34: Total Monthly Cost | B34: =SUM(B31:B33) | C34: =SUM(C31:C33)
A35: Total Upfront Cost | B35: =SUM(B13,B18) | C35: =SUM(C13,C18)
A37: Cash Flow
A38: Unit Configurations (Bed,Bath,Sqrft) | B38: Configuration | C38: Estimated Rent
A39: Unit 1 | B39: 2-bed 2-bath | C39: =VLOOKUP(B39,$E$2:$F$8,2,FALSE)
A40: Unit 2 | B40: 2-bed 1-bath | C40: =VLOOKUP(B40,$E$2:$F$8,2,FALSE)
A41: Unit 3 | B41: None | C41: =VLOOKUP(B41,$E$2:$F$8,2,FALSE)
A42: Unit 4 | B42: None | C42: =VLOOKUP(B42,$E$2:$F$8,2,FALSE)
A43: Living in Unit… | B43: Unit 2
...

Sheet 401 Franklin Ave
A1: Property Details | B1: 401 Franklin Ave, Des Moines, IA 50314 | E1: Conservative Claude Report Assumptions | F1: Per Month
A2: Multi-unit Type | B2: 2 | E2: 1-bed 1-bath | F2: 0
A3: Purchase Price | B3: 199900 | E3: 2-bed 1-bath | F3: 0
A4: Square Feet | B4: 2381 | E4: 3-bed 1-bath | F4: 0
A5: Bedrooms | B5: 5 | E5: 2-bed 2-bath | F5: 1147
A6: Bathrooms | B6: 4 | E6: 3-bed 2-bath | F6: 1395
A7: Lot Size (Sqr ft) | B7: 0 | E7: Studio | F7: 0
A8: Built in Year | B8: 1901 | E8: None | F8: 0
A9: Cost Per Square Foot | B9: =B3/B4
A12: Financials
A13: Closing Costs | B13: =$B$3*Assumptions!$B$5 | C13: =$B$3*Assumptions!$B$5
A14: Rehab Costs (Optional)
A15: Mortgage
A16: Loan Type | B16: FHA | C16: Conventional - 5%
A17: Down payment percentage | B17: =IF(B16="Conventional - 5%",0.05,0.035) | C17: =IF(C16="Conventional - 5%",0.05,0.035)
A18: Down payment amount | B18: =$B$3*B17 | C18: =$B$3*C17
A19: Base Loan Amount | B19: =$B$3-B18 | C19: =$B$3-C18
A20: FHA Fees Rolled into Loan | B20: =B3*Assumptions!$B$7 | C20: 0
A21: Final Loan Amount | B21: =B19+B20 | C21: =C19+C20
A22: Interest Rate | B22: =Assumptions!$B$6 | C22: =Assumptions!$B$6
A23: Monthly Mortgage Payment | B23: =PMT(B22/12,Assumptions!$B$9*12, -B21) | C23: =PMT(C22/12,Assumptions!$B$9*12, -C21)
A24: PMI Annual Cost | B24: =B21*Assumptions!$B$8 | C24: =C21*Assumptions!$B$8
A25: PMI Monthly Cost | B25: =B24/12 | C25: =C24/12
A26: Total PMI Cost Over the Whole Loan | B26: =B25*12*Assumptions!$B$9 | C26: =C25*12*Assumptions!$B$9
A27: Property Tax Percentage | B27: =$B$3*Assumptions!$B$2 | C27: =$B$3*Assumptions!$B$2
A28: Property Tax Per Month | B28: =B27/12 | C28: =C27/12
A29: Home Insurance Cost Per Year | B29: =$B$3*Assumptions!$B$10 | C29: =$B$3*Assumptions!$B$10
A30: Home Insurance Cost Per Month | B30: =B29/12 | C30: =C29/12
A31: Mortgage + Taxes + Insurance Monthly | B31: =B23+B25+B30+B28 | C31: =C23+C25+C30+C28
A32: Vacancy Cost Savings Per Month | B32: =Assumptions!$B$3*B31 | C32: =Assumptions!$B$3*C31
A33: Repair Cost Savings Per Month | B33: =B31*Assumptions!$B$4 | C33: =C31*Assumptions!$B$4
A34: Total Monthly Cost | B34: =SUM(B31:B33) | C34: =SUM(C31:C33)
A35: Total Upfront Cost | B35: =SUM(B13,B18) | C35: =SUM(C13,C18)
A37: Cash Flow
A38: Unit Configurations (Bed,Bath,Sqrft) | B38: Configuration | C38: Estimated Rent
A39: Unit 1 | B39: 2-bed 2-bath | C39: =VLOOKUP(B39,$E$2:$F$8,2,FALSE)
A40: Unit 2 | B40: 3-bed 2-bath | C40: =VLOOKUP(B40,$E$2:$F$8,2,FALSE)
A41: Unit 3 | B41: None | C41: =VLOOKUP(B41,$E$2:$F$8,2,FALSE)
A42: Unit 4 | B42: None | C42: =VLOOKUP(B42,$E$2:$F$8,2,FALSE)
A43: Living in Unit… | B43: Unit 1
...

Sheet 1608 Mondamin Ave
A1: Property Details | B1: 1608 Mondamin Ave, Des Moines, IA 50314 | E1: Conservative Claude Report Assumptions | F1: Per Month
A2: Multi-unit Type | B2: 2 | E2: 1-bed 1-bath | F2: 0
A3: Purchase Price | B3: 240000 | E3: 2-bed 1-bath | F3: 1195
A4: Square Feet | B4: 1056 | E4: 3-bed 1-bath | F4: 0
A5: Bedrooms | B5: 4 | E5: 2-bed 2-bath | F5: 0
A6: Bathrooms | B6: 2 | E6: 3-bed 3-bath | F6: 0
A7: Lot Size (Sqr ft) | B7: 0 | E7: Studio | F7: 0
A8: Built in Year | B8: 1936 | E8: None | F8: 0
A9: Cost Per Square Foot | B9: =B3/B4
A12: Financials
A13: Closing Costs | B13: =$B$3*Assumptions!$B$5 | C13: =$B$3*Assumptions!$B$5
A14: Rehab Costs (Optional)
A15: Mortgage
A16: Loan Type | B16: FHA | C16: Conventional - 5%
A17: Down payment percentage | B17: =IF(B16="Conventional - 5%",0.05,0.035) | C17: =IF(C16="Conventional - 5%",0.05,0.035)
A18: Down payment amount | B18: =$B$3*B17 | C18: =$B$3*C17
A19: Base Loan Amount | B19: =$B$3-B18 | C19: =$B$3-C18
A20: FHA Fees Rolled into Loan | B20: =B3*Assumptions!$B$7 | C20: 0
A21: Final Loan Amount | B21: =B19+B20 | C21: =C19+C20
A22: Interest Rate | B22: =Assumptions!$B$6 | C22: =Assumptions!$B$6
A23: Monthly Mortgage Payment | B23: =PMT(B22/12,Assumptions!$B$9*12, -B21) | C23: =PMT(C22/12,Assumptions!$B$9*12, -C21)
A24: PMI Annual Cost | B24: =B21*Assumptions!$B$8 | C24: =C21*Assumptions!$B$8
A25: PMI Monthly Cost | B25: =B24/12 | C25: =C24/12
A26: Total PMI Cost Over the Whole Loan | B26: =B25*12*Assumptions!$B$9 | C26: =C25*12*Assumptions!$B$9
A27: Property Tax Percentage | B27: =$B$3*Assumptions!$B$2 | C27: =$B$3*Assumptions!$B$2
A28: Property Tax Per Month | B28: =B27/12 | C28: =C27/12
A29: Home Insurance Cost Per Year | B29: =$B$3*Assumptions!$B$10 | C29: =$B$3*Assumptions!$B$10
A30: Home Insurance Cost Per Month | B30: =B29/12 | C30: =C29/12
A31: Mortgage + Taxes + Insurance Monthly | B31: =B23+B25+B30+B28 | C31: =C23+C25+C30+C28
A32: Vacancy Cost Savings Per Month | B32: =Assumptions!$B$3*B31 | C32: =Assumptions!$B$3*C31
A33: Repair Cost Savings Per Month | B33: =B31*Assumptions!$B$4 | C33: =C31*Assumptions!$B$4
A34: Total Monthly Cost | B34: =SUM(B31:B33) | C34: =SUM(C31:C33)
A35: Total Upfront Cost | B35: =SUM(B13,B18) | C35: =SUM(C13,C18)
A37: Cash Flow
A38: Unit Configurations (Bed,Bath,Sqrft) | B38: Configuration | C38: Estimated Rent
A39: Unit 1 | B39: 2-bed 1-bath | C39: =VLOOKUP(B39,$E$2:$F$8,2,FALSE)
A40: Unit 2 | B40: 2-bed 1-bath | C40: =VLOOKUP(B40,$E$2:$F$8,2,FALSE)
A41: Unit 3 | B41: None | C41: =VLOOKUP(B41,$E$2:$F$8,2,FALSE)
A42: Unit 4 | B42: None | C42: =VLOOKUP(B42,$E$2:$F$8,2,FALSE)
A43: Living in Unit… | B43: Unit 2
...

Sheet 1064 27th St
A1: Property Details | B1: 1064 27th St, Des Moines, IA 50311 | E1: Conservative Claude Report Assumptions | F1: Per Month
A2: Multi-unit Type | B2: 2 | E2: 1-bed 1-bath | F2: 0
A3: Purchase Price | B3: 259900 | E3: 2-bed 1-bath | F3: 1175
A4: Square Feet | B4: 1856 | E4: 3-bed 1-bath | F4: 1398
A5: Bedrooms | B5: 5 | E5: 2-bed 2-bath | F5: 0
A6: Bathrooms | B6: 2 | E6: 3-bed 3-bath | F6: 0
A7: Lot Size (Sqr ft) | B7: 0 | E7: Studio | F7: 0
A8: Built in Year | B8: 1900 | E8: None | F8: 0
A9: Cost Per Square Foot | B9: =B3/B4
A12: Financials
A13: Closing Costs | B13: =$B$3*Assumptions!$B$5 | C13: =$B$3*Assumptions!$B$5
A14: Rehab Costs (Optional)
A15: Mortgage
A16: Loan Type | B16: FHA | C16: Conventional - 5%
A17: Down payment percentage | B17: =IF(B16="Conventional - 5%",0.05,0.035) | C17: =IF(C16="Conventional - 5%",0.05,0.035)
A18: Down payment amount | B18: =$B$3*B17 | C18: =$B$3*C17
A19: Base Loan Amount | B19: =$B$3-B18 | C19: =$B$3-C18
A20: FHA Fees Rolled into Loan | B20: =B3*Assumptions!$B$7 | C20: 0
A21: Final Loan Amount | B21: =B19+B20 | C21: =C19+C20
A22: Interest Rate | B22: =Assumptions!$B$6 | C22: =Assumptions!$B$6
A23: Monthly Mortgage Payment | B23: =PMT(B22/12,Assumptions!$B$9*12, -B21) | C23: =PMT(C22/12,Assumptions!$B$9*12, -C21)
A24: PMI Annual Cost | B24: =B21*Assumptions!$B$8 | C24: =C21*Assumptions!$B$8
A25: PMI Monthly Cost | B25: =B24/12 | C25: =C24/12
A26: Total PMI Cost Over the Whole Loan | B26: =B25*12*Assumptions!$B$9 | C26: =C25*12*Assumptions!$B$9
A27: Property Tax Percentage | B27: =$B$3*Assumptions!$B$2 | C27: =$B$3*Assumptions!$B$2
A28: Property Tax Per Month | B28: =B27/12 | C28: =C27/12
A29: Home Insurance Cost Per Year | B29: =$B$3*Assumptions!$B$10 | C29: =$B$3*Assumptions!$B$10
A30: Home Insurance Cost Per Month | B30: =B29/12 | C30: =C29/12
A31: Mortgage + Taxes + Insurance Monthly | B31: =B23+B25+B30+B28 | C31: =C23+C25+C30+C28
A32: Vacancy Cost Savings Per Month | B32: =Assumptions!$B$3*B31 | C32: =Assumptions!$B$3*C31
A33: Repair Cost Savings Per Month | B33: =B31*Assumptions!$B$4 | C33: =C31*Assumptions!$B$4
A34: Total Monthly Cost | B34: =SUM(B31:B33) | C34: =SUM(C31:C33)
A35: Total Upfront Cost | B35: =SUM(B13,B18) | C35: =SUM(C13,C18)
A37: Cash Flow
A38: Unit Configurations (Bed,Bath,Sqrft) | B38: Configuration | C38: Estimated Rent
A39: Unit 1 | B39: 3-bed 1-bath | C39: =VLOOKUP(B39,$E$2:$F$8,2,FALSE)
A40: Unit 2 | B40: 2-bed 1-bath | C40: =VLOOKUP(B40,$E$2:$F$8,2,FALSE)
A41: Unit 3 | B41: None | C41: =VLOOKUP(B41,$E$2:$F$8,2,FALSE)
A42: Unit 4 | B42: None | C42: =VLOOKUP(B42,$E$2:$F$8,2,FALSE)
A43: Living in Unit… | B43: Unit 2
...

Sheet 518 35th St
A1: Property Details | B1: 518 35th St, Des Moines, IA 50312 | E1: Conservative Claude Report Assumptions | F1: Per Month
A2: Multi-unit Type | B2: 4 | E2: 1-bed 1-bath | F2: 840
A3: Purchase Price | B3: 264900 | E3: 2-bed 1-bath | F3: 1150
A4: Square Feet | B4: 2463 | E4: 3-bed 1-bath | F4: 0
A5: Bedrooms | B5: 5 | E5: 2-bed 2-bath | F5: 0
A6: Bathrooms | B6: 4 | E6: 3-bed 3-bath | F6: 0
A7: Lot Size (Sqr ft) | E7: Studio | F7: 740
A8: Built in Year | B8: 1909
A9: Cost Per Square Foot | B9: =B3/B4
A12: Financials
A13: Closing Costs | B13: =$B$3*Assumptions!$B$5 | C13: =$B$3*Assumptions!$B$5
A14: Rehab Costs (Optional)
A15: Mortgage
A16: Loan Type | B16: FHA | C16: Conventional - 5%
A17: Down payment percentage | B17: =IF(B16="Conventional - 5%",0.05,0.035) | C17: =IF(C16="Conventional - 5%",0.05,0.035)
A18: Down payment amount | B18: =$B$3*B17 | C18: =$B$3*C17
A19: Base Loan Amount | B19: =$B$3-B18 | C19: =$B$3-C18
A20: FHA Fees Rolled into Loan | B20: =B3*Assumptions!$B$7 | C20: 0
A21: Final Loan Amount | B21: =B19+B20 | C21: =C19+C20
A22: Interest Rate | B22: =Assumptions!$B$6 | C22: =Assumptions!$B$6
A23: Monthly Mortgage Payment | B23: =PMT(B22/12,Assumptions!$B$9*12, -'518 35th St'!B21) | C23: =PMT(C22/12,Assumptions!$B$9*12, -'518 35th St'!C21)
A24: PMI Annual Cost | B24: =B21*Assumptions!$B$8 | C24: =C21*Assumptions!$B$8
A25: PMI Monthly Cost | B25: =B24/12 | C25: =C24/12
A26: Total PMI Cost Over the Whole Loan | B26: =B25*12*Assumptions!$B$9 | C26: =C25*12*Assumptions!$B$9
A27: Property Tax Percentage | B27: =$B$3*Assumptions!$B$2 | C27: =$B$3*Assumptions!$B$2
A28: Property Tax Per Month | B28: =B27/12 | C28: =C27/12
A29: Home Insurance Cost Per Year | B29: =$B$3*Assumptions!$B$10 | C29: =$B$3*Assumptions!$B$10
A30: Home Insurance Cost Per Month | B30: =B29/12 | C30: =C29/12
A31: Mortgage + Taxes + Insurance Monthly | B31: =B23+B25+B30+B28 | C31: =C23+C25+C30+C28
A32: Vacancy Cost Savings Per Month | B32: =Assumptions!$B$3*'518 35th St'!B31 | C32: =Assumptions!$B$3*'518 35th St'!C31
A33: Repair Cost Savings Per Month | B33: =B31*Assumptions!$B$4 | C33: =C31*Assumptions!$B$4
A34: Total Monthly Cost | B34: =SUM(B31:B33) | C34: =SUM(C31:C33)
A35: Total Upfront Cost | B35: =SUM(B13,B18) | C35: =SUM(C13,C18)
A37: Cash Flow
A38: Unit Configurations (Bed,Bath,Sqrft) | B38: Configuration | C38: Estimated Rent
A39: Unit 1 | B39: Studio | C39: =VLOOKUP(B39,$E$2:$F$7,2,FALSE)
A40: Unit 2 | B40: 1-bed 1-bath | C40: =VLOOKUP(B40,$E$2:$F$5,2,FALSE)
A41: Unit 3 | B41: 2-bed 1-bath | C41: =VLOOKUP(B41,$E$2:$F$5,2,FALSE)
A42: Unit 4 | B42: 2-bed 1-bath | C42: =VLOOKUP(B42,$E$2:$F$5,2,FALSE)
A43: Living in Unit… | B43: Unit 1
...

Sheet 1148 36th St
A1: Property Details | B1: 1148 36th St, Des Moines, IA 50311 | E1: Conservative Claude Report Assumptions | F1: Per Month
A2: Multi-unit Type | B2: 4 | E2: 1-bed 1-bath | F2: 825
A3: Purchase Price | B3: 355000 | E3: 2-bed 1-bath | F3: 925
A4: Square Feet | B4: 2509 | E4: 3-bed 1-bath | F4: 0
A5: Bedrooms | B5: 6 | E5: 2-bed 2-bath | F5: 0
A6: Bathrooms | B6: 4 | E6: 3-bed 3-bath | F6: 0
A7: Lot Size (Sqr ft)
A8: Built in Year | B8: 1907
A9: Cost Per Square Foot | B9: =B3/B4
A12: Financials
A13: Closing Costs | B13: =$B$3*Assumptions!$B$5 | C13: =$B$3*Assumptions!$B$5
A14: Rehab Costs (Optional)
A15: Mortgage
A16: Loan Type | B16: FHA | C16: Conventional - 10%
A17: Down payment percentage | B17: =IF(B16="Conventional - 5%",0.05,0.035) | C17: =IF(C16="Conventional - 5%",0.05,0.035)
A18: Down payment amount | B18: =$B$3*B17 | C18: =$B$3*C17
A19: Base Loan Amount | B19: =$B$3-B18 | C19: =$B$3-C18
A20: FHA Fees Rolled into Loan | B20: =B3*Assumptions!$B$7 | C20: 0
A21: Final Loan Amount | B21: =B19+B20 | C21: =C19+C20
A22: Interest Rate | B22: =Assumptions!$B$6 | C22: =Assumptions!$B$6
A23: Monthly Mortgage Payment | B23: =PMT(B22/12,Assumptions!$B$9*12, -'1148 36th St'!B21) | C23: =PMT(C22/12,Assumptions!$B$9*12, -'1148 36th St'!C21)
A24: PMI Annual Cost | B24: =B21*Assumptions!$B$8 | C24: =C21*Assumptions!$B$8
A25: PMI Monthly Cost | B25: =B24/12 | C25: =C24/12
A26: Total PMI Cost Over the Whole Loan | B26: =B25*12*Assumptions!$B$9 | C26: =C25*12*Assumptions!$B$9
A27: Property Tax Percentage | B27: =$B$3*Assumptions!$B$2 | C27: =$B$3*Assumptions!$B$2
A28: Property Tax Per Month | B28: =B27/12 | C28: =C27/12
A29: Home Insurance Cost Per Year | B29: =$B$3*Assumptions!$B$10 | C29: =$B$3*Assumptions!$B$10
A30: Home Insurance Cost Per Month | B30: =B29/12 | C30: =C29/12
A31: Mortgage + Taxes + Insurance Monthly | B31: =B23+B25+B30+B28 | C31: =C23+C25+C30+C28
A32: Vacancy Cost Savings Per Month | B32: =Assumptions!$B$3*'1148 36th St'!B31 | C32: =Assumptions!$B$3*'1148 36th St'!C31
A33: Repair Cost Savings Per Month | B33: =B31*Assumptions!$B$4 | C33: =C31*Assumptions!$B$4
A34: Total Monthly Cost | B34: =SUM(B31:B33) | C34: =SUM(C31:C33)
A35: Total Upfront Cost | B35: =SUM(B13,B18) | C35: =SUM(C13,C18)
A37: Cash Flow
A38: Unit Configurations (Bed,Bath,Sqrft) | B38: Configuration | C38: Estimated Rent
A39: Unit 1 | B39: 1-bed 1-bath | C39: =VLOOKUP(B39,$E$2:$F$5,2,FALSE)
A40: Unit 2 | B40: 1-bed 1-bath | C40: =VLOOKUP(B40,$E$2:$F$5,2,FALSE)
A41: Unit 3 | B41: 2-bed 1-bath | C41: =VLOOKUP(B41,$E$2:$F$5,2,FALSE)
A42: Unit 4 | B42: 2-bed 1-bath | C42: =VLOOKUP(B42,$E$2:$F$5,2,FALSE)
A43: Living in Unit… | B43: Unit 1
...

Sheet template
A1: Property Details | B1: ADDRESS_HERE | E1: Conservative Claude Report Assumptions | F1: Per Month
A2: Multi-unit Type | B2: 0 | E2: 1-bed 1-bath | F2: 0
A3: Purchase Price | B3: 0 | E3: 2-bed 1-bath | F3: 0
A4: Square Feet | B4: 0 | E4: 3-bed 1-bath | F4: 0
A5: Bedrooms | B5: 0 | E5: 2-bed 2-bath | F5: 0
A6: Bathrooms | B6: 0 | E6: 4-bed 2-bath | F6: 0
A7: Lot Size (Sqr ft) | B7: 0 | E7: Studio | F7: 0
A8: Built in Year | B8: 0 | E8: None | F8: 0
A9: Cost Per Square Foot | B9: =B3/B4 | E9: 3-bed 2-bath | F9: 0
E10: 3-bed 3-bath | F10: 0
A12: Financials
A13: Closing Costs | B13: =$B$3*Assumptions!$B$5 | C13: =$B$3*Assumptions!$B$5
A14: Rehab Costs (Optional)
A15: Mortgage
A16: Loan Type | B16: FHA | C16: Conventional - 5%
A17: Down payment percentage | B17: =IF(B16="Conventional - 5%",0.05,0.035) | C17: =IF(C16="Conventional - 5%",0.05,0.035)
A18: Down payment amount | B18: =$B$3*B17 | C18: =$B$3*C17
A19: Base Loan Amount | B19: =$B$3-B18 | C19: =$B$3-C18
A20: FHA Fees Rolled into Loan | B20: =B3*Assumptions!$B$7 | C20: 0
A21: Final Loan Amount | B21: =B19+B20 | C21: =C19+C20
A22: Interest Rate | B22: =Assumptions!$B$6 | C22: =Assumptions!$B$6
A23: Monthly Mortgage Payment | B23: =PMT(B22/12,Assumptions!$B$9*12, -B21) | C23: =PMT(C22/12,Assumptions!$B$9*12, -C21)
A24: PMI Annual Cost | B24: =B21*Assumptions!$B$8 | C24: =C21*Assumptions!$B$8
A25: PMI Monthly Cost | B25: =B24/12 | C25: =C24/12
A26: Total PMI Cost Over the Whole Loan | B26: =B25*12*Assumptions!$B$9 | C26: =C25*12*Assumptions!$B$9
A27: Property Tax Percentage | B27: =$B$3*Assumptions!$B$2 | C27: =$B$3*Assumptions!$B$2
A28: Property Tax Per Month | B28: =B27/12 | C28: =C27/12
A29: Home Insurance Cost Per Year | B29: =$B$3*Assumptions!$B$10 | C29: =$B$3*Assumptions!$B$10
A30: Home Insurance Cost Per Month | B30: =B29/12 | C30: =C29/12
A31: Mortgage + Taxes + Insurance Monthly | B31: =B23+B25+B30+B28 | C31: =C23+C25+C30+C28
A32: Vacancy Cost Savings Per Month | B32: =Assumptions!$B$3*B31 | C32: =Assumptions!$B$3*C31
A33: Repair Cost Savings Per Month | B33: =B31*Assumptions!$B$4 | C33: =C31*Assumptions!$B$4
A34: Total Monthly Cost | B34: =SUM(B31:B33) | C34: =SUM(C31:C33)
A35: Total Upfront Cost | B35: =SUM(B13,B18) | C35: =SUM(C13,C18)
A37: Cash Flow
A38: Unit Configurations (Bed,Bath,Sqrft) | B38: Configuration | C38: Estimated Rent
A39: Unit 1 | B39: None | C39: =VLOOKUP(B39,$E$2:$F$10,2,FALSE)
A40: Unit 2 | B40: None | C40: =VLOOKUP(B40,$E$2:$F$10,2,FALSE)
A41: Unit 3 | B41: None | C41: =VLOOKUP(B41,$E$2:$F$10,2,FALSE)
A42: Unit 4 | B42: None | C42: =VLOOKUP(B42,$E$2:$F$10,2,FALSE)
...

Sheet 3900 11th St
A1: Property Details | B1: 3900 11th St, Des Moines, IA 50313 | E1: Conservative Claude Report Assumptions | F1: Per Month
A2: Multi-unit Type | B2: 3 | E2: 1-bed 1-bath | F2: 0
A3: Purchase Price | B3: 225000 | E3: 2-bed 1-bath | F3: 0
A4: Square Feet | B4: 2851 | E4: 3-bed 1-bath | F4: 0
A5: Bedrooms | B5: 6 | E5: 2-bed 2-bath | F5: 0
A6: Bathrooms | B6: 3 | E6: 4-bed 2-bath | F6: 0
A7: Lot Size (Sqr ft) | B7: 0 | E7: Studio | F7: 0
A8: Built in Year | B8: 1909 | E8: None | F8: 0
A9: Cost Per Square Foot | B9: =B3/B4 | E9: 3-bed 2-bath | F9: 0
E10: 3-bed 3-bath | F10: 0
A12: Financials
A13: Closing Costs | B13: =$B$3*Assumptions!$B$5 | C13: =$B$3*Assumptions!$B$5
A14: Rehab Costs (Optional)
A15: Mortgage
A16: Loan Type | B16: FHA | C16: Conventional - 5%
A17: Down payment percentage | B17: =IF(B16="Conventional - 5%",0.05,0.035) | C17: =IF(C16="Conventional - 5%",0.05,0.035)
A18: Down payment amount | B18: =$B$3*B17 | C18: =$B$3*C17
A19: Base Loan Amount | B19: =$B$3-B18 | C19: =$B$3-C18
A20: FHA Fees Rolled into Loan | B20: =B3*Assumptions!$B$7 | C20: 0
A21: Final Loan Amount | B21: =B19+B20 | C21: =C19+C20
A22: Interest Rate | B22: =Assumptions!$B$6 | C22: =Assumptions!$B$6
A23: Monthly Mortgage Payment | B23: =PMT(B22/12,Assumptions!$B$9*12, -B21) | C23: =PMT(C22/12,Assumptions!$B$9*12, -C21)
A24: PMI Annual Cost | B24: =B21*Assumptions!$B$8 | C24: =C21*Assumptions!$B$8
A25: PMI Monthly Cost | B25: =B24/12 | C25: =C24/12
A26: Total PMI Cost Over the Whole Loan | B26: =B25*12*Assumptions!$B$9 | C26: =C25*12*Assumptions!$B$9
A27: Property Tax Percentage | B27: =$B$3*Assumptions!$B$2 | C27: =$B$3*Assumptions!$B$2
A28: Property Tax Per Month | B28: =B27/12 | C28: =C27/12
A29: Home Insurance Cost Per Year | B29: =$B$3*Assumptions!$B$10 | C29: =$B$3*Assumptions!$B$10
A30: Home Insurance Cost Per Month | B30: =B29/12 | C30: =C29/12
A31: Mortgage + Taxes + Insurance Monthly | B31: =B23+B25+B30+B28 | C31: =C23+C25+C30+C28
A32: Vacancy Cost Savings Per Month | B32: =Assumptions!$B$3*B31 | C32: =Assumptions!$B$3*C31
A33: Repair Cost Savings Per Month | B33: =B31*Assumptions!$B$4 | C33: =C31*Assumptions!$B$4
A34: Total Monthly Cost | B34: =SUM(B31:B33) | C34: =SUM(C31:C33)
A35: Total Upfront Cost | B35: =SUM(B13,B18) | C35: =SUM(C13,C18)
A37: Cash Flow
A38: Unit Configurations (Bed,Bath,Sqrft) | B38: Configuration | C38: Estimated Rent
A39: Unit 1 | B39: 2-beds 1-baths | C39: 1125
A40: Unit 2 | B40: 2-beds 1-baths | C40: 1125
A41: Unit 3 | B41: 2-beds 1-baths | C41: 1125
A42: Unit 4 | B42: None | C42: =VLOOKUP(B42,$E$2:$F$10,2,FALSE)
...
